[2022-01-13 12:29:05,973] {taskinstance.py:1032} INFO - Dependencies all met for <TaskInstance: my_dag.processing_user scheduled__2022-01-12T04:34:30.714488+00:00 [queued]>
[2022-01-13 12:29:05,977] {taskinstance.py:1032} INFO - Dependencies all met for <TaskInstance: my_dag.processing_user scheduled__2022-01-12T04:34:30.714488+00:00 [queued]>
[2022-01-13 12:29:05,977] {taskinstance.py:1238} INFO - 
--------------------------------------------------------------------------------
[2022-01-13 12:29:05,977] {taskinstance.py:1239} INFO - Starting attempt 4 of 4
[2022-01-13 12:29:05,977] {taskinstance.py:1240} INFO - 
--------------------------------------------------------------------------------
[2022-01-13 12:29:05,991] {taskinstance.py:1259} INFO - Executing <Task(PythonOperator): processing_user> on 2022-01-12 04:34:30.714488+00:00
[2022-01-13 12:29:05,993] {standard_task_runner.py:52} INFO - Started process 26159 to run task
[2022-01-13 12:29:05,995] {standard_task_runner.py:76} INFO - Running: ['airflow', 'tasks', 'run', 'my_dag', 'processing_user', 'scheduled__2022-01-12T04:34:30.714488+00:00', '--job-id', '15', '--raw', '--subdir', 'DAGS_FOLDER/my_dag.py', '--cfg-path', '/tmp/tmp_3vbzohd', '--error-file', '/tmp/tmpf6af7co1']
[2022-01-13 12:29:05,996] {standard_task_runner.py:77} INFO - Job 15: Subtask processing_user
[2022-01-13 12:29:06,028] {logging_mixin.py:109} INFO - Running <TaskInstance: my_dag.processing_user scheduled__2022-01-12T04:34:30.714488+00:00 [running]> on host gianghoatran-Vostro-3591
[2022-01-13 12:29:06,054] {taskinstance.py:1424} INFO - Exporting the following env vars:
AIRFLOW_CTX_DAG_OWNER=airflow
AIRFLOW_CTX_DAG_ID=my_dag
AIRFLOW_CTX_TASK_ID=processing_user
AIRFLOW_CTX_EXECUTION_DATE=2022-01-12T04:34:30.714488+00:00
AIRFLOW_CTX_DAG_RUN_ID=scheduled__2022-01-12T04:34:30.714488+00:00
[2022-01-13 12:29:06,057] {taskinstance.py:1700} ERROR - Task failed with exception
Traceback (most recent call last):
  File "/home/gianghoatran/MyCode/airflow/env/lib/python3.8/site-packages/airflow/models/taskinstance.py", line 1329, in _run_raw_task
    self._execute_task_with_callbacks(context)
  File "/home/gianghoatran/MyCode/airflow/env/lib/python3.8/site-packages/airflow/models/taskinstance.py", line 1455, in _execute_task_with_callbacks
    result = self._execute_task(context, self.task)
  File "/home/gianghoatran/MyCode/airflow/env/lib/python3.8/site-packages/airflow/models/taskinstance.py", line 1511, in _execute_task
    result = execute_callable(context=context)
  File "/home/gianghoatran/MyCode/airflow/env/lib/python3.8/site-packages/airflow/operators/python.py", line 174, in execute
    return_value = self.execute_callable()
  File "/home/gianghoatran/MyCode/airflow/env/lib/python3.8/site-packages/airflow/operators/python.py", line 185, in execute_callable
    return self.python_callable(*self.op_args, **self.op_kwargs)
  File "/home/gianghoatran/MyCode/airflow/dags/my_dag.py", line 13, in processing_user_extracted
    processed_user.to_csv('/tmp/test.csv', index=None, header=False)
AttributeError: 'str' object has no attribute 'to_csv'
[2022-01-13 12:29:06,060] {taskinstance.py:1267} INFO - Marking task as FAILED. dag_id=my_dag, task_id=processing_user, execution_date=20220112T043430, start_date=20220113T052905, end_date=20220113T052906
[2022-01-13 12:29:06,075] {standard_task_runner.py:89} ERROR - Failed to execute job 15 for task processing_user
Traceback (most recent call last):
  File "/home/gianghoatran/MyCode/airflow/env/lib/python3.8/site-packages/airflow/task/task_runner/standard_task_runner.py", line 85, in _start_by_fork
    args.func(args, dag=self.dag)
  File "/home/gianghoatran/MyCode/airflow/env/lib/python3.8/site-packages/airflow/cli/cli_parser.py", line 48, in command
    return func(*args, **kwargs)
  File "/home/gianghoatran/MyCode/airflow/env/lib/python3.8/site-packages/airflow/utils/cli.py", line 92, in wrapper
    return f(*args, **kwargs)
  File "/home/gianghoatran/MyCode/airflow/env/lib/python3.8/site-packages/airflow/cli/commands/task_command.py", line 298, in task_run
    _run_task_by_selected_method(args, dag, ti)
  File "/home/gianghoatran/MyCode/airflow/env/lib/python3.8/site-packages/airflow/cli/commands/task_command.py", line 107, in _run_task_by_selected_method
    _run_raw_task(args, ti)
  File "/home/gianghoatran/MyCode/airflow/env/lib/python3.8/site-packages/airflow/cli/commands/task_command.py", line 180, in _run_raw_task
    ti._run_raw_task(
  File "/home/gianghoatran/MyCode/airflow/env/lib/python3.8/site-packages/airflow/utils/session.py", line 70, in wrapper
    return func(*args, session=session, **kwargs)
  File "/home/gianghoatran/MyCode/airflow/env/lib/python3.8/site-packages/airflow/models/taskinstance.py", line 1329, in _run_raw_task
    self._execute_task_with_callbacks(context)
  File "/home/gianghoatran/MyCode/airflow/env/lib/python3.8/site-packages/airflow/models/taskinstance.py", line 1455, in _execute_task_with_callbacks
    result = self._execute_task(context, self.task)
  File "/home/gianghoatran/MyCode/airflow/env/lib/python3.8/site-packages/airflow/models/taskinstance.py", line 1511, in _execute_task
    result = execute_callable(context=context)
  File "/home/gianghoatran/MyCode/airflow/env/lib/python3.8/site-packages/airflow/operators/python.py", line 174, in execute
    return_value = self.execute_callable()
  File "/home/gianghoatran/MyCode/airflow/env/lib/python3.8/site-packages/airflow/operators/python.py", line 185, in execute_callable
    return self.python_callable(*self.op_args, **self.op_kwargs)
  File "/home/gianghoatran/MyCode/airflow/dags/my_dag.py", line 13, in processing_user_extracted
    processed_user.to_csv('/tmp/test.csv', index=None, header=False)
AttributeError: 'str' object has no attribute 'to_csv'
[2022-01-13 12:29:06,087] {local_task_job.py:154} INFO - Task exited with return code 1
[2022-01-13 12:29:06,118] {local_task_job.py:264} INFO - 0 downstream tasks scheduled from follow-on schedule check
