[2022-01-13 14:48:28,226] {taskinstance.py:1032} INFO - Dependencies all met for <TaskInstance: my_dag.is_api_available scheduled__2022-01-12T04:34:30.714488+00:00 [queued]>
[2022-01-13 14:48:28,233] {taskinstance.py:1032} INFO - Dependencies all met for <TaskInstance: my_dag.is_api_available scheduled__2022-01-12T04:34:30.714488+00:00 [queued]>
[2022-01-13 14:48:28,233] {taskinstance.py:1238} INFO - 
--------------------------------------------------------------------------------
[2022-01-13 14:48:28,233] {taskinstance.py:1239} INFO - Starting attempt 11 of 11
[2022-01-13 14:48:28,233] {taskinstance.py:1240} INFO - 
--------------------------------------------------------------------------------
[2022-01-13 14:48:28,251] {taskinstance.py:1259} INFO - Executing <Task(HttpSensor): is_api_available> on 2022-01-12 04:34:30.714488+00:00
[2022-01-13 14:48:28,255] {standard_task_runner.py:52} INFO - Started process 39365 to run task
[2022-01-13 14:48:28,261] {standard_task_runner.py:76} INFO - Running: ['airflow', 'tasks', 'run', 'my_dag', 'is_api_available', 'scheduled__2022-01-12T04:34:30.714488+00:00', '--job-id', '28', '--raw', '--subdir', 'DAGS_FOLDER/my_dag.py', '--cfg-path', '/tmp/tmphd126sna', '--error-file', '/tmp/tmpcgc41h5h']
[2022-01-13 14:48:28,262] {standard_task_runner.py:77} INFO - Job 28: Subtask is_api_available
[2022-01-13 14:48:28,309] {logging_mixin.py:109} INFO - Running <TaskInstance: my_dag.is_api_available scheduled__2022-01-12T04:34:30.714488+00:00 [running]> on host gianghoatran-Vostro-3591
[2022-01-13 14:48:28,340] {taskinstance.py:1424} INFO - Exporting the following env vars:
AIRFLOW_CTX_DAG_OWNER=airflow
AIRFLOW_CTX_DAG_ID=my_dag
AIRFLOW_CTX_TASK_ID=is_api_available
AIRFLOW_CTX_EXECUTION_DATE=2022-01-12T04:34:30.714488+00:00
AIRFLOW_CTX_DAG_RUN_ID=scheduled__2022-01-12T04:34:30.714488+00:00
[2022-01-13 14:48:28,340] {http.py:101} INFO - Poking: user/GiangHoaTran
[2022-01-13 14:48:28,344] {base.py:70} INFO - Using connection to: id: user_api. Host: http://127.0.0.1:8000/, Port: None, Schema: , Login: , Password: None, extra: {}
[2022-01-13 14:48:28,345] {http.py:140} INFO - Sending 'GET' to url: http://127.0.0.1:8000/user/GiangHoaTran
[2022-01-13 14:48:28,699] {http.py:154} ERROR - HTTP error: Internal Server Error
[2022-01-13 14:48:28,700] {http.py:155} ERROR - Internal Server Error
[2022-01-13 14:48:28,707] {taskinstance.py:1700} ERROR - Task failed with exception
Traceback (most recent call last):
  File "/home/gianghoatran/MyCode/airflow/env/lib/python3.8/site-packages/airflow/providers/http/hooks/http.py", line 152, in check_response
    response.raise_for_status()
  File "/home/gianghoatran/MyCode/airflow/env/lib/python3.8/site-packages/requests/models.py", line 953, in raise_for_status
    raise HTTPError(http_error_msg, response=self)
requests.exceptions.HTTPError: 500 Server Error: Internal Server Error for url: http://127.0.0.1:8000/user/GiangHoaTran

During handling of the above exception, another exception occurred:

Traceback (most recent call last):
  File "/home/gianghoatran/MyCode/airflow/env/lib/python3.8/site-packages/airflow/models/taskinstance.py", line 1329, in _run_raw_task
    self._execute_task_with_callbacks(context)
  File "/home/gianghoatran/MyCode/airflow/env/lib/python3.8/site-packages/airflow/models/taskinstance.py", line 1455, in _execute_task_with_callbacks
    result = self._execute_task(context, self.task)
  File "/home/gianghoatran/MyCode/airflow/env/lib/python3.8/site-packages/airflow/models/taskinstance.py", line 1511, in _execute_task
    result = execute_callable(context=context)
  File "/home/gianghoatran/MyCode/airflow/env/lib/python3.8/site-packages/airflow/sensors/base.py", line 234, in execute
    while not self.poke(context):
  File "/home/gianghoatran/MyCode/airflow/env/lib/python3.8/site-packages/airflow/providers/http/sensors/http.py", line 117, in poke
    raise exc
  File "/home/gianghoatran/MyCode/airflow/env/lib/python3.8/site-packages/airflow/providers/http/sensors/http.py", line 103, in poke
    response = self.hook.run(
  File "/home/gianghoatran/MyCode/airflow/env/lib/python3.8/site-packages/airflow/providers/http/hooks/http.py", line 141, in run
    return self.run_and_check(session, prepped_request, extra_options)
  File "/home/gianghoatran/MyCode/airflow/env/lib/python3.8/site-packages/airflow/providers/http/hooks/http.py", line 198, in run_and_check
    self.check_response(response)
  File "/home/gianghoatran/MyCode/airflow/env/lib/python3.8/site-packages/airflow/providers/http/hooks/http.py", line 156, in check_response
    raise AirflowException(str(response.status_code) + ":" + response.reason)
airflow.exceptions.AirflowException: 500:Internal Server Error
[2022-01-13 14:48:28,716] {taskinstance.py:1267} INFO - Marking task as FAILED. dag_id=my_dag, task_id=is_api_available, execution_date=20220112T043430, start_date=20220113T074828, end_date=20220113T074828
[2022-01-13 14:48:28,740] {standard_task_runner.py:89} ERROR - Failed to execute job 28 for task is_api_available
Traceback (most recent call last):
  File "/home/gianghoatran/MyCode/airflow/env/lib/python3.8/site-packages/airflow/providers/http/hooks/http.py", line 152, in check_response
    response.raise_for_status()
  File "/home/gianghoatran/MyCode/airflow/env/lib/python3.8/site-packages/requests/models.py", line 953, in raise_for_status
    raise HTTPError(http_error_msg, response=self)
requests.exceptions.HTTPError: 500 Server Error: Internal Server Error for url: http://127.0.0.1:8000/user/GiangHoaTran

During handling of the above exception, another exception occurred:

Traceback (most recent call last):
  File "/home/gianghoatran/MyCode/airflow/env/lib/python3.8/site-packages/airflow/task/task_runner/standard_task_runner.py", line 85, in _start_by_fork
    args.func(args, dag=self.dag)
  File "/home/gianghoatran/MyCode/airflow/env/lib/python3.8/site-packages/airflow/cli/cli_parser.py", line 48, in command
    return func(*args, **kwargs)
  File "/home/gianghoatran/MyCode/airflow/env/lib/python3.8/site-packages/airflow/utils/cli.py", line 92, in wrapper
    return f(*args, **kwargs)
  File "/home/gianghoatran/MyCode/airflow/env/lib/python3.8/site-packages/airflow/cli/commands/task_command.py", line 298, in task_run
    _run_task_by_selected_method(args, dag, ti)
  File "/home/gianghoatran/MyCode/airflow/env/lib/python3.8/site-packages/airflow/cli/commands/task_command.py", line 107, in _run_task_by_selected_method
    _run_raw_task(args, ti)
  File "/home/gianghoatran/MyCode/airflow/env/lib/python3.8/site-packages/airflow/cli/commands/task_command.py", line 180, in _run_raw_task
    ti._run_raw_task(
  File "/home/gianghoatran/MyCode/airflow/env/lib/python3.8/site-packages/airflow/utils/session.py", line 70, in wrapper
    return func(*args, session=session, **kwargs)
  File "/home/gianghoatran/MyCode/airflow/env/lib/python3.8/site-packages/airflow/models/taskinstance.py", line 1329, in _run_raw_task
    self._execute_task_with_callbacks(context)
  File "/home/gianghoatran/MyCode/airflow/env/lib/python3.8/site-packages/airflow/models/taskinstance.py", line 1455, in _execute_task_with_callbacks
    result = self._execute_task(context, self.task)
  File "/home/gianghoatran/MyCode/airflow/env/lib/python3.8/site-packages/airflow/models/taskinstance.py", line 1511, in _execute_task
    result = execute_callable(context=context)
  File "/home/gianghoatran/MyCode/airflow/env/lib/python3.8/site-packages/airflow/sensors/base.py", line 234, in execute
    while not self.poke(context):
  File "/home/gianghoatran/MyCode/airflow/env/lib/python3.8/site-packages/airflow/providers/http/sensors/http.py", line 117, in poke
    raise exc
  File "/home/gianghoatran/MyCode/airflow/env/lib/python3.8/site-packages/airflow/providers/http/sensors/http.py", line 103, in poke
    response = self.hook.run(
  File "/home/gianghoatran/MyCode/airflow/env/lib/python3.8/site-packages/airflow/providers/http/hooks/http.py", line 141, in run
    return self.run_and_check(session, prepped_request, extra_options)
  File "/home/gianghoatran/MyCode/airflow/env/lib/python3.8/site-packages/airflow/providers/http/hooks/http.py", line 198, in run_and_check
    self.check_response(response)
  File "/home/gianghoatran/MyCode/airflow/env/lib/python3.8/site-packages/airflow/providers/http/hooks/http.py", line 156, in check_response
    raise AirflowException(str(response.status_code) + ":" + response.reason)
airflow.exceptions.AirflowException: 500:Internal Server Error
[2022-01-13 14:48:28,753] {local_task_job.py:154} INFO - Task exited with return code 1
[2022-01-13 14:48:28,788] {local_task_job.py:264} INFO - 0 downstream tasks scheduled from follow-on schedule check
